Workbook

Sheet How to read this
A1: BOTIn — PRD vs concern sheet vs catalogue
A3: Three sources, reconciled one L2 at a time. Nothing here is a decision — it is the document that lets decisions be made.
A5: THE THREE SOURCES
A6: 1. Concern sheet "PX Outbound- YM Sathi" — June, 59,171 tickets. 7 L1 paths, 113 decision rules, per-L2 flow status. The only source with conditions, counters and caps.
A7: 2. PRD "PX — Outbound Model — BOT Intervention" — May, 50,130 tickets. 5 L1 paths, 36 L2 flows, tiers, agent-connect triggers, NFRs, rollout phases.
A8: 3. The catalogue concern_catalogue, 38 rows — what the service is actually configured to do today. Built FROM the concern sheet: every June volume matches exactly.
A10: SO THE COMPARISON IS REALLY TWO-WAY
A11: The catalogue is the concern sheet, in database form. The disagreement is sheet+catalogue on one side, PRD on the other.
A13: THE VERDICT COLUMN
A14: AGREE — both describe the same thing compatibly. Build it.
A15: CONFLICT — they describe incompatible things. Someone must choose before this is built.
A16: SHEET ONLY — in the sheet and the catalogue, absent from the PRD.
... A23: The PRD's 86% and the sheet's 61.5% are both estimates of the same quantity. See the "Headline gap" tab.

Sheet Reconciliation
A1: L1 (sheet) | B1: L2 (as in June data) | C1: June vol | D1: Sheet flow status | E1: Sheet deflection % | F1: Sheet reroutes to | G1: Catalogue code | H1: Active | I1: Rules | J1: Build state | K1: PRD path | L1: PRD tier | M1: VERDICT | N1: Decision needed | O1: Sheet basis for its assumption
A2: Violations | B2: Violation | C2: 9769 | D2: DEFINED | E2: 0.7 | G2: VIOL_* (17 rows) | H2: Y | I2: 54 | J2: SEEDED, no code | K2: — (no Violations path) | L2: — | M2: SHEET ONLY | N2: VIOL_R4_OTHERS is built (free-text router); the other 16 are seeded only. Largest single block: 9,769 + 12,781 fines folding in = 22,550/mo. PRD has no Violations L1; strike appeal sits under Other Related. Decide where Violations lives, and whether it returns to scope. | O2: Most Type-2 reasons decide on objective data (distance, timestamps, counters) and upholds close without an agent. Ticket branches: rude behaviour, <Rs800, R9 logistics, R13, cap-exceeded, R2 call-contradiction, T3 pushback.
A3: Fine Related | B3: rule break fine/Other fines | C3: 6362 | D3: DEPRECATED | E3: 0.7 | F3: Violations | G3: FINE_ALL | H3: N | I3: 1 | J3: DEPRECATED | K3: Fine Related | L3: T2 | M3: CONFLICT | N3: Sheet DEPRECATES the whole Fine L1 into the strike system; PRD keeps it live with its own flow. 6,362/mo. One of these is wrong. | O3: Fines now link to the strike system only — these become violation challenges and inherit the Violations rate.
A4: Fine Related | B4: Leaves fine | C4: 6085 | D4: DEPRECATED | E4: 0.7 | F4: Violations | G4: FINE_ALL | H4: N | I4: 1 | J4: DEPRECATED | K4: Fine Related | L4: T2 | M4: CONFLICT | N4: Same conflict as rule-break fine. 6,085/mo. | O4: Same as above — leave fines fold into Type-1 same-day-leave violation logic.
A5: Fine Related | B5: Late job Fine | C5: 185 | D5: DEPRECATED | E5: 0.7 | F5: Violations | G5: FINE_ALL | H5: N | I5: 1 | J5: DEPRECATED | K5: — | L5: — | M5: SHEET ONLY | N5: Job-related fines being stopped; residual only. Confirm retirement. | O5: Job-related fines being stopped; residual folds into strikes.
A6: Fine Related | B6: Expert issue with customer rating | C6: 124 | D6: DEPRECATED | E6: 0.4 | F6: Violations / Other-data | G6: FINE_ALL | H6: N | I6: 1 | J6: DEPRECATED | K6: Other Related | L6: T3 | M6: AGREE | N6: Both route it away from the bot. Sheet deprecates to Violations/Other-data; PRD makes it T3. Same outcome, different home. | O6: Rating corrections need customer confirmation → mostly agent.
A7: Fine Related | B7: Escalations fine | C7: 25 | D7: DEPRECATED | E7: 0.9 | F7: Violations | G7: FINE_ALL | H7: N | I7: 1 | J7: DEPRECATED | K7: Fine Related | L7: T1 | M7: CONFLICT | N7: Sheet deprecates; PRD keeps as T1 non-refundable message. Low volume (25) but the policy must be stated somewhere. | O7: Escalation fines are non-refundable — a clean deny-and-explain.
A8: Amount Related | B8: Transport amount nahi mila | C8: 5615 | D8: DEFINED | E8: 0.85 | G8: TRANSPORT_NOT_RECEIVED | H8: Y | I8: 9 | J8: BUILT | K8: Amount related | L8: T2 | M8: AGREE | N8: No decision needed. BUILT. Blocked only on the data answers (N2, Q6, paise-vs-rupees, arrived_at300_m). | O8: Nearly every branch is a bot decision (arrivedAt300metre, cancellation status, haversine). Tickets only when >Rs300 cap or the CR-without-cashback anomaly.
A9: Amount Related | B9: Online Booking Ke pese nahi mile | C9: 1868 | D9: DEFINED | E9: 0.67 | F9: ~85% reroutes out | G9: ONLINE_BOOKING_MONEY | H9: Y | I9: 5 | J9: SEEDED, no code | K9: Amount related | L9: T3 | M9: AGREE | N9: No decision needed. Seeded, not built. | O9: 85% mis-tagged → inherit destination rates (~70%); of the genuine 15%, prepaid-flag mismatches auto-credit but mixed/COD disputes need an agent (~50%).
A10: Amount Related | B10: Saving <Rs5000 → bank transfer | C10: 1042 | D10: DEPRECATED | E10: 0.8 | F10: ARW transfer | G10: SAVING_UNDER_5K | H10: N | I10: 1 | J10: DEPRECATED | K10: Amount related | L10: T2 | M10: CONFLICT | N10: Sheet: Rs5,000 minimum REMOVED, 100% mis-tagged, DEPRECATED. PRD: live T2 rule check. 1,042/mo. Confirm the minimum is really gone. | O10: Rs5,000 minimum removed — 100% mis-tagged, inherits the ARW blocker-explain rate.
A11: Amount Related | B11: Recharge kiya pese cut gaye aaye nahi | C11: 883 | D11: DEFINED | E11: 0.75 | G11: RECHARGE_DEBIT_NO_CREDIT | H11: Y | I11: 4 | J11: BUILT | K11: Amount related | L11: T2 | M11: AGREE | N11: No decision needed. BUILT. Blocked on N3 (the PayU link). | O11: Failed and pending-at-PayU both resolve in chat; success-not-credited auto-credits. Only PayU-pending and dissatisfied-SP cases ticket.
A12: Amount Related | B12: Forget MPIN | C12: 738 | D12: DEFINED | E12: 1 | G12: FORGET_MPIN | H12: Y | I12: 1 | J12: BUILT | K12: Amount related | L12: T1 | M12: AGREE | N12: No decision needed. BUILT and fully working — the only concern live today. | O12: Single deeplink, no backend check, no exceptions.
A13: Amount Related | B13: Saving account ke paise Bank account me Transfer (ARW) | C13: 650 | D13: DEFINED | E13: 0.8 | G13: ARW_TO_BANK | H13: Y | I13: 6 | J13: SEEDED, no code | K13: Amount related | L13: T1 | M13: AGREE | N13: Tier differs (sheet implies bot action, PRD T1 explain). Minor — confirm whether the bot transfers or explains. | O13: Four hard blockers (negative wallet, advance pending, 5-txn, Rs40k) are all deny-and-explain; only the unexplained-failure branch tickets.
A14: Amount Related | B14: Wallet ke paise Bank account me Transfer | C14: 316 | D14: DEFINED | E14: 0.85 | G14: MAIN_WALLET_TO_BANK | H14: Y | I14: 3 | J14: SEEDED, no code | K14: Amount related | L14: T1 | M14: AGREE | N14: As above. | O14: Rs500 floor and Cashfree-low both resolve in chat.
A15: Amount Related | B15: Mera account verify kr dijiye | C15: 163 | D15: PARTIAL | E15: 0.1 | G15: — | H15: — | I15: — | J15: not in catalogue | K15: Amount related | L15: T2 | M15: CONFLICT | N15: Sheet marks PARTIAL at 10% deflection — "bot can read status but the action needs a human". PRD makes it T2 auto-action. Decide which. | O15: Bot can read verification status but the Verify action is agent-side in v1. Auto-verify API would take this to ~90%.
A16: Amount Related | B16: Booking banwani hai | C16: 7 | D16: DEFINED | E16: 1 | F16: Other: booking deeplink | G16: OTHER_BOOKING_REQ | H16: Y | I16: 1 | J16: REROUTE — inherits its target | K16: Other Related | L16: T1 | M16: AGREE | N16: Self-serve deeplink. Sheet has it under both Amount and Other; PRD under Other. Pick one home. | O16: Self-serve deeplink.
A17: Amount Related | B17: Want to rejoin | C17: 1 | D17: NOT DEFINED | E17: 0 | G17: — | H17: — | I17: — | J17: not in catalogue | K17: — | L17: — | M17: NO FLOW | N17: 1/mo. Leave undefined or route to agent. | O17: No flow specified.
A18: Product Issues | B18: Product out of stock | C18: 2807 | D18: DEFINED | E18: 0.25 | G18: PROD_OUT_OF_STOCK | H18: Y | I18: 3 | J18: SEEDED, no code | K18: — (no Product path) | L18: — | M18: SHEET ONLY | N18: PRD has no Product Issues L1 at all. 2,807/mo, and the sheet flags only the category-mismatch branch as automatable. | O18: CAUTION: only the category-mismatch branch resolves in chat. Both a genuine stock-out AND a false out-of-stock create a ticket by design.
A19: Product Issues | B19: 3 Din se jyada ho gaye product nahi aaya (Delay in delivery) | C19: 2306 | D19: DEFINED | E19: 0.45 | G19: PROD_DELIVERY_DELAY | H19: Y | I19: 2 | J19: BUILT | K19: — (no Product path) | L19: — | M19: SHEET ONLY | N19: BUILT, tested, 2,306/mo — and has nowhere to live in the PRD. This is the sharpest single example of the taxonomy gap. | O19: Within-TAT cases resolve with an expected-date message; anything past the 11 PM deadline is a logistics ticket.
A20: Product Issues | B20: App se Product nahi lag pa raha | C20: 873 | D20: DEFINED | E20: 0.15 | G20: PROD_APP_FAILURE | H20: Y | I20: 2 | J20: SEEDED, no code | K20: — (no Product path) | L20: — | M20: SHEET ONLY | N20: Defined outcome is a tech ticket. 873/mo. | O20: Defined outcome is a tech ticket; only mis-described cases reroute out.
A21: Product Issues | B21: Missing Product Request | C21: 638 | D21: NOT DEFINED | E21: 0 | G21: — | H21: — | I21: — | J21: not in catalogue | K21: — | L21: — | M21: NO FLOW | N21: L2 deferred by the sheet; absent from the PRD. | O21: L2 deferred.
A22: Product Issues | B22: Product me koi issue | C22: 549 | D22: NOT DEFINED | E22: 0 | G22: — | H22: — | I22: — | J22: not in catalogue | K22: — | L22: — | M22: NO FLOW | N22: L2 deferred by the sheet; absent from the PRD. | O22: L2 deferred.
A23: Product Issues | B23: Product Payment related issue | C23: 514 | D23: NOT DEFINED | E23: 0 | F23: Likely Amount L1 | G23: — | H23: — | I23: — | J23: not in catalogue | K23: — | L23: — | M23: NO FLOW | N23: Sheet suggests it may reroute into Amount. Confirm. | O23: L2 deferred — may reroute into Amount flows once defined.
A24: Product Issues | B24: Kit Related Issue | C24: 389 | D24: NOT DEFINED | E24: 0 | G24: — | H24: — | I24: — | J24: not in catalogue | K24: — | L24: — | M24: NO FLOW | N24: L2 deferred; absent from the PRD. | O24: L2 deferred.
A25: Product Issues | B25: Delivery boy Complaint | C25: 158 | D25: NOT DEFINED | E25: 0 | G25: — | H25: — | I25: — | J25: not in catalogue | K25: — | L25: — | M25: NO FLOW | N25: L2 deferred; absent from the PRD. | O25: L2 deferred.
A26: Product Issues | B26: Jo Product Deliver hua hai Wo Damage hai | C26: 78 | D26: NOT DEFINED | E26: 0 | G26: — | H26: — | I26: — | J26: not in catalogue | K26: — | L26: — | M26: NO FLOW | N26: L2 deferred; absent from the PRD. | O26: L2 deferred.
A27: Product Issues | B27: Damage Product Request | C27: 6 | D27: NOT DEFINED | E27: 0 | G27: — | H27: — | I27: — | J27: not in catalogue | K27: — | L27: — | M27: NO FLOW | N27: L2 deferred; absent from the PRD. | O27: L2 deferred.
A28: Other issues | B28: Other any issue | C28: 4640 | D28: DEFINED | E28: 0.6 | F28: Reroutes across engine | G28: OTHER_FREETEXT_TRIAGE | H28: Y | I28: 2 | J28: BUILT | K28: — (free-text triage) | L28: — | M28: SHEET ONLY | N28: BUILT. 4,640/mo of mis-tagged traffic that the triage classifier reroutes. The PRD assumes audio-note L1 selection instead. | O28: Free-text triage sends most of these to a defined flow (inheriting ~70%); the genuinely unclassifiable residual tickets.
A29: Other issues | B29: Hub/Time change karwana hai | C29: 2635 | D29: DEFINED | E29: 0.45 | G29: OTHER_HUB_TIME | H29: Y | I29: 3 | J29: SEEDED, no code | K29: Other Related | L29: T2/T1 | M29: AGREE | N29: PRD splits this into "Hub add/delete" and "Shift-time change". Sheet keeps one L2. Decide whether to split the catalogue row. | O29: Time-INCREASE is a self-serve deeplink; hub-change is always a ticket; reduce-hours is undecided. Rate depends on the hub-vs-time split — measure it.
A30: Other issues | B30: Mere Partner App me Data Wrong Show ho raha hai | C30: 1771 | D30: DEFINED | E30: 0.25 | G30: OTHER_WRONG_DATA | H30: Y | I30: 1 | J30: SEEDED, no code | K30: Other Related | L30: T1 | M30: AGREE | N30: No decision needed. Seeded, not built. | O30: Only the monthly-summary-before-the-10th case explains away; specific count and rating errors go to RM/agent.
A31: Other issues | B31: Call masking issue | C31: 600 | D31: NOT DEFINED | E31: 0 | G31: — | H31: — | I31: — | J31: not in catalogue | K31: — | L31: — | M31: NO FLOW | N31: 600/mo. Direct ticket per the original SOP; no rule defined and absent from the PRD. | O31: Direct ticket per original SOP; no rule built.
A32: Other issues | B32: Id Active/Deactivate Karani hai | C32: 394 | D32: DEFINED | E32: 0.05 | G32: OTHER_ID_ACTIVATE | H32: Y | I32: 1 | J32: SEEDED, no code | K32: Other Related | L32: T1 | M32: AGREE | N32: No decision needed. | O32: Defined outcome is a ticket after reason capture.
A33: Other issues | B33: Booking banwani hai | C33: 128 | D33: DEFINED | E33: 1 | G33: OTHER_BOOKING_REQ | H33: Y | I33: 1 | J33: SEEDED, no code | K33: Other Related | L33: T1 | M33: AGREE | N33: Self-serve deeplink. Sheet has it under both Amount and Other; PRD under Other. Pick one home. | O33: Self-serve deeplink.
A34: Other issues | B34: Issue with Customer / Block Customer | C34: 48 | D34: DEFINED | E34: 0.9 | G34: OTHER_BLOCK_CUSTOMER | H34: Y | I34: 1 | J34: SEEDED, no code | K34: — | L34: — | M34: SHEET ONLY | N34: Fully automated block from backend. Absent from the PRD. | O34: Fully automated block from backend after confirm.
A35: Other issues | B35: Leave hata dijiye | C35: 32 | D35: DEFINED | E35: 0.85 | F35: Leaves | G35: — | H35: — | I35: — | J35: not in catalogue | K35: Other Related | L35: T2 | M35: AGREE | N35: No decision needed. | O35: Auto-check of who marked the leave; company-side is deny-and-explain, SP-side auto-removes.
A36: Other issues | B36: Transport amount nahi mila | C36: 5 | D36: DEFINED | E36: 0.85 | F36: Amount: transport | G36: TRANSPORT_NOT_RECEIVED | H36: Y | I36: 9 | J36: REROUTE — inherits its target | K36: Amount related | L36: T2 | M36: AGREE | N36: No decision needed. BUILT. Blocked only on the data answers (N2, Q6, paise-vs-rupees, arrived_at300_m). | O36: Mis-tagged; inherits transport rate.
A37: Other issues | B37: Expert ko shift time change karwana hai | C37: 3 | D37: DEFINED | E37: 0.5 | F37: Hub/Time | G37: — | H37: — | I37: — | J37: REROUTE — inherits its target | K37: — | L37: — | M37: NO FLOW | N37: Not matched to a PRD concern. | O37: Inherits hub/time rate.
A38: Other issues | B38: Late job Fine | C38: 1 | D38: DEPRECATED | E38: 0.7 | F38: Violations | G38: FINE_ALL | H38: N | I38: 1 | J38: REROUTE — inherits its target | K38: — | L38: — | M38: SHEET ONLY | N38: Job-related fines being stopped; residual only. Confirm retirement. | O38: Mis-tagged; inherits Violations rate.
A39: Job Related | B39: Job nahi aa rahi hai | C39: 1438 | D39: PROJECTED | E39: 0.8 | G39: — | H39: — | I39: — | J39: not in catalogue | K39: Realtime Job | L39: T1 | M39: PRD AHEAD | N39: Sheet says the whole L1 is unspecified; the PRD specifies it. Take the PRD as the source here. | O39: PROJECTION — L1 not yet specified. Profile diagnostic (visibility, hubs, leave, live slot) resolves most; only genuine config faults ticket.
A40: Job Related | B40: Door ki job hai | C40: 910 | D40: PROJECTED | E40: 0.7 | F40: Reuses far-job logic | G40: — | H40: — | I40: — | J40: not in catalogue | K40: Realtime Job | L40: T2 | M40: PRD AHEAD | N40: PRD folds this into "Job pe nahi jana" with a reason dropdown. | O40: PROJECTION — >1hr to booking is a self-serve reject; <1hr needs live handling.
...

Sheet By verdict
A1: Verdict | B1: Concerns | C1: June volume | D1: Share of volume | E1: What it means
A2: CONFLICT | B2: =COUNTIF(Reconciliation!$M$2:$M$69,$A2) -> 6 | C2: =SUMIF(Reconciliation!$M$2:$M$69,$A2,Reconciliation!$C$2:$C$69) -> 13677 | D2: =IFERROR($C2/$C$8,0) -> 0.22971498 | E2: Incompatible. A person must choose before any of this is built.
A3: NO FLOW | B3: =COUNTIF(Reconciliation!$M$2:$M$69,$A3) -> 11 | C3: =SUMIF(Reconciliation!$M$2:$M$69,$A3,Reconciliation!$C$2:$C$69) -> 3000 | D3: =IFERROR($C3/$C$8,0) -> 0.050387141 | E3: Neither source has a flow. Route to an agent, or drop.
A4: SHEET ONLY | B4: =COUNTIF(Reconciliation!$M$2:$M$69,$A4) -> 8 | C4: =SUMIF(Reconciliation!$M$2:$M$69,$A4,Reconciliation!$C$2:$C$69) -> 20629 | D4: =IFERROR($C4/$C$8,0) -> 0.34647878 | E4: In the catalogue, absent from the PRD. Decide whether it stays in scope.
A5: PRD ONLY | B5: =COUNTIF(Reconciliation!$M$2:$M$69,$A5) -> 3 | C5: =SUMIF(Reconciliation!$M$2:$M$69,$A5,Reconciliation!$C$2:$C$69) -> 0 | D5: =IFERROR($C5/$C$8,0) -> 0 | E5: In the PRD, absent from the catalogue. Confirm it is real and get its volume.
A6: PRD AHEAD | B6: =COUNTIF(Reconciliation!$M$2:$M$69,$A6) -> 9 | C6: =SUMIF(Reconciliation!$M$2:$M$69,$A6,Reconciliation!$C$2:$C$69) -> 3807 | D6: =IFERROR($C6/$C$8,0) -> 0.063941282 | E6: Sheet says unspecified, PRD specifies. Take the PRD as the source.
A7: AGREE | B7: =COUNTIF(Reconciliation!$M$2:$M$69,$A7) -> 31 | C7: =SUMIF(Reconciliation!$M$2:$M$69,$A7,Reconciliation!$C$2:$C$69) -> 18426 | D7: =IFERROR($C7/$C$8,0) -> 0.30947782 | E7: Both sources compatible. Buildable once the data answers land.
A8: TOTAL | B8: =SUM(B2:B7) -> 68 | C8: =SUM(C2:C7) -> 59539 | D8: =IFERROR(C8/C8,0) -> 1
A10: Volume is the sheet's June figure. Rows with no volume (PRD-only concerns, and concerns the sheet lists without a count) contribute 0, so the shares understate them.

Sheet By L1
A1: L1 | B1: Concerns | C1: June volume | D1: Conflicts | E1: No flow | F1: Agreed | G1: Built today
A2: Violations | B2: =COUNTIF(Reconciliation!$A$2:$A$69,$A2) -> 1 | C2: =SUMIF(Reconciliation!$A$2:$A$69,$A2,Reconciliation!$C$2:$C$69) -> 9769 | D2: =COUNTIFS(Reconciliation!$A$2:$A$69,$A2,Reconciliation!$M$2:$M$69,"CONFLICT") -> 0 | E2: =COUNTIFS(Reconciliation!$A$2:$A$69,$A2,Reconciliation!$M$2:$M$69,"NO FLOW") -> 0 | F2: =COUNTIFS(Reconciliation!$A$2:$A$69,$A2,Reconciliation!$M$2:$M$69,"AGREE") -> 0 | G2: =COUNTIFS(Reconciliation!$A$2:$A$69,$A2,Reconciliation!$J$2:$J$69,"BUILT") -> 0
A3: Fine Related | B3: =COUNTIF(Reconciliation!$A$2:$A$69,$A3) -> 5 | C3: =SUMIF(Reconciliation!$A$2:$A$69,$A3,Reconciliation!$C$2:$C$69) -> 12781 | D3: =COUNTIFS(Reconciliation!$A$2:$A$69,$A3,Reconciliation!$M$2:$M$69,"CONFLICT") -> 3 | E3: =COUNTIFS(Reconciliation!$A$2:$A$69,$A3,Reconciliation!$M$2:$M$69,"NO FLOW") -> 0 | F3: =COUNTIFS(Reconciliation!$A$2:$A$69,$A3,Reconciliation!$M$2:$M$69,"AGREE") -> 1 | G3: =COUNTIFS(Reconciliation!$A$2:$A$69,$A3,Reconciliation!$J$2:$J$69,"BUILT") -> 0
A4: Amount Related | B4: =COUNTIF(Reconciliation!$A$2:$A$69,$A4) -> 13 | C4: =SUMIF(Reconciliation!$A$2:$A$69,$A4,Reconciliation!$C$2:$C$69) -> 11651 | D4: =COUNTIFS(Reconciliation!$A$2:$A$69,$A4,Reconciliation!$M$2:$M$69,"CONFLICT") -> 2 | E4: =COUNTIFS(Reconciliation!$A$2:$A$69,$A4,Reconciliation!$M$2:$M$69,"NO FLOW") -> 1 | F4: =COUNTIFS(Reconciliation!$A$2:$A$69,$A4,Reconciliation!$M$2:$M$69,"AGREE") -> 9 | G4: =COUNTIFS(Reconciliation!$A$2:$A$69,$A4,Reconciliation!$J$2:$J$69,"BUILT") -> 3
A5: Product Issues | B5: =COUNTIF(Reconciliation!$A$2:$A$69,$A5) -> 10 | C5: =SUMIF(Reconciliation!$A$2:$A$69,$A5,Reconciliation!$C$2:$C$69) -> 8318 | D5: =COUNTIFS(Reconciliation!$A$2:$A$69,$A5,Reconciliation!$M$2:$M$69,"CONFLICT") -> 0 | E5: =COUNTIFS(Reconciliation!$A$2:$A$69,$A5,Reconciliation!$M$2:$M$69,"NO FLOW") -> 7 | F5: =COUNTIFS(Reconciliation!$A$2:$A$69,$A5,Reconciliation!$M$2:$M$69,"AGREE") -> 0 | G5: =COUNTIFS(Reconciliation!$A$2:$A$69,$A5,Reconciliation!$J$2:$J$69,"BUILT") -> 1
A6: Other issues | B6: =COUNTIF(Reconciliation!$A$2:$A$69,$A6) -> 14 | C6: =SUMIF(Reconciliation!$A$2:$A$69,$A6,Reconciliation!$C$2:$C$69) -> 10257 | D6: =COUNTIFS(Reconciliation!$A$2:$A$69,$A6,Reconciliation!$M$2:$M$69,"CONFLICT") -> 1 | E6: =COUNTIFS(Reconciliation!$A$2:$A$69,$A6,Reconciliation!$M$2:$M$69,"NO FLOW") -> 2 | F6: =COUNTIFS(Reconciliation!$A$2:$A$69,$A6,Reconciliation!$M$2:$M$69,"AGREE") -> 8 | G6: =COUNTIFS(Reconciliation!$A$2:$A$69,$A6,Reconciliation!$J$2:$J$69,"BUILT") -> 1
A7: Job Related | B7: =COUNTIF(Reconciliation!$A$2:$A$69,$A7) -> 13 | C7: =SUMIF(Reconciliation!$A$2:$A$69,$A7,Reconciliation!$C$2:$C$69) -> 3872 | D7: =COUNTIFS(Reconciliation!$A$2:$A$69,$A7,Reconciliation!$M$2:$M$69,"CONFLICT") -> 0 | E7: =COUNTIFS(Reconciliation!$A$2:$A$69,$A7,Reconciliation!$M$2:$M$69,"NO FLOW") -> 1 | F7: =COUNTIFS(Reconciliation!$A$2:$A$69,$A7,Reconciliation!$M$2:$M$69,"AGREE") -> 1 | G7: =COUNTIFS(Reconciliation!$A$2:$A$69,$A7,Reconciliation!$J$2:$J$69,"BUILT") -> 0
A8: Leaves Related | B8: =COUNTIF(Reconciliation!$A$2:$A$69,$A8) -> 12 | C8: =SUMIF(Reconciliation!$A$2:$A$69,$A8,Reconciliation!$C$2:$C$69) -> 2891 | D8: =COUNTIFS(Reconciliation!$A$2:$A$69,$A8,Reconciliation!$M$2:$M$69,"CONFLICT") -> 0 | E8: =COUNTIFS(Reconciliation!$A$2:$A$69,$A8,Reconciliation!$M$2:$M$69,"NO FLOW") -> 0 | F8: =COUNTIFS(Reconciliation!$A$2:$A$69,$A8,Reconciliation!$M$2:$M$69,"AGREE") -> 12 | G8: =COUNTIFS(Reconciliation!$A$2:$A$69,$A8,Reconciliation!$J$2:$J$69,"BUILT") -> 0
A9: TOTAL | B9: =SUM(B2:B8) -> 68 | C9: =SUM(C2:C8) -> 59539 | D9: =SUM(D2:D8) -> 6 | E9: =SUM(E2:E8) -> 11 | F9: =SUM(F2:F8) -> 31 | G9: =SUM(G2:G8) -> 5
A11: Total is 59,539 against the sheet's 59,171. The 368 difference is Cashback (176) and Referral (192) — both in the sheet's Decision Matrix and in the catalogue, but missing from its Volume Model tab. That is an inconsistency inside the concern sheet, not an error here.

Sheet Headline gap
A1: The two documents disagree about the business case by a quarter of all volume
A3: Source | B3: Says | C3: Basis | D3: Shown its working?
A4: PRD §7.2 | B4: 86.0% bot-handled (T0+T1+T2), 14.0% agent | C4: May, 50,130 tickets | D4: No — a top-down tier split with no per-concern derivation
A5: Concern sheet, L1 Rollup | B5: 61.5% resolved without an agent | C5: June, 59,171 tickets | D5: Yes — a deflection assumption per L2, each with a written basis
A6: Concern sheet, Outcome Summary | B6: 69.0% of BRANCHES need no human | C6: 113 decision branches | D6: Yes — and it carries its own caveat that branches are not volume
A8: Why this matters more than it looks
A9: The 86% is the number in the business case, and the 61.5% is the number derived from the rules that were actually written. They measure the same thing: share needing no human.
A10: The sheet is the more careful estimate — bottom-up, per concern, with its assumptions flagged as editable by its own author. It is also the more recent month.
A11: Neither is measured. Both are forecasts. The only way to know is to log what the bot WOULD have decided beside what an agent actually did, before anything is switched on.
A13: What to do about it
A14: Settle which number the business case commits to before anything is built against it, and state which document it came from.
A15: If the 86% stands, the gap has to be found somewhere — most plausibly in Violations, which the sheet puts at 70% deflection over 22,550 monthly cases and the PRD does not model at all.

Sheet Decisions needed
A1: # | B1: Decision | C1: Volume at stake | D1: Why it cannot wait | E1: Who
A2: 1 | B2: Does the Fine L1 stay live, or fold into the strike system? | C2: 12781 | D2: Sheet deprecates the entire L1 into Violations; PRD keeps three live flows. The two describe incompatible systems, and this is the second-largest block of volume. | E2: Product
A3: 2 | B3: Is Violations in scope, and where does it live? | C3: 9769 | D3: The sheet's largest single L1, at 70% deflection. The PRD has no Violations path — strike appeals appear as ONE T1 row under Other Related, against 17 concerns and 54 rules in the sheet. It was removed from POC scope in September. | E3: Product + Engineering
A4: 3 | B4: Does Product Issues exist as an L1? | C4: 8318 | D4: Absent from the PRD entirely. PROD_DELIVERY_DELAY is built, tested and carries 2,306/mo with nowhere to live. Seven further L2s are undefined in both. | E4: Product
A5: 4 | B5: Which headline number does the business case commit to — 86% or 61.5%? | C5: 0 | D5: They differ by a quarter of all volume and both are forecasts. Everything downstream — staffing, the agent-connect target, the phase gates — is sized off this. | E5: Product + Leadership
A6: 5 | B6: Is the Rs5,000 savings minimum really removed? | C6: 1042 | D6: Sheet says removed and the concern 100% mis-tagged, so DEPRECATED. PRD keeps it as a live T2 rule check. | E6: Product
A7: 6 | B7: Account verification: T2 auto-action or human? | C7: 163 | D7: Sheet marks PARTIAL at 10% deflection — the bot can read status but not act. PRD makes it T2. | E7: Product
A8: 7 | B8: Job Related — adopt the PRD as the source for this L1? | C8: 3872 | D8: The sheet says the entire L1 is unspecified. The PRD specifies eleven flows and most of the new capabilities R-01 to R-10 live inside it. Confirm the PRD wins here. | E8: Product + Engineering
A9: 8 | B9: The 2,933/mo with no flow in either document. | C9: 2933 | D9: Eleven concerns where neither source defines anything. Under NFR-01 every one of them still has to be reachable through Help at launch, even if only to reach an agent. | E9: Product
B11: Volume at stake is the sheet's June figure for the concerns the decision covers.
