Workbook

Sheet Summary
A1: BOTIn POC — where we are
A2: Formulas over the Steps tab. Change a Status there and everything here updates. Statuses in use: Done · In progress · Not started · Blocked (waiting on somebody) · Parked (deliberately deferred — the Parked tab says what unparks each) · Out of scope (removed from the POC by decision — not waiting on anybody).
A3: TARGET: a working chatbot POC — L1 → L2 → resolution, API-driven, every tier and outcome type.
A5: Track | B5: Total | C5: Done | D5: Delivered | E5: In progress | F5: Blocked | G5: Parked | H5: Not started | I5: Out of scope | J5: Where it stands
A6: R&D ladder | B6: =COUNTIF(Steps!$B$2:$B$99,$A6) | C6: =COUNTIFS(Steps!$B$2:$B$99,$A6,Steps!$G$2:$G$99,"Done") | D6: =COUNTIFS(Steps!$B$2:$B$99,$A6,Steps!$G$2:$G$99,"Delivered") | E6: =COUNTIFS(Steps!$B$2:$B$99,$A6,Steps!$G$2:$G$99,"In progress") | F6: =COUNTIFS(Steps!$B$2:$B$99,$A6,Steps!$G$2:$G$99,"Blocked") | G6: =COUNTIFS(Steps!$B$2:$B$99,$A6,Steps!$G$2:$G$99,"Parked") | H6: =COUNTIFS(Steps!$B$2:$B$99,$A6,Steps!$G$2:$G$99,"Not started") | I6: =COUNTIFS(Steps!$B$2:$B$99,$A6,Steps!$G$2:$G$99,"Out of scope") | J6: COMPLETE. Six spikes, all green. Both go/no-go gates passed.
A7: Build | B7: =COUNTIF(Steps!$B$2:$B$99,$A7) | C7: =COUNTIFS(Steps!$B$2:$B$99,$A7,Steps!$G$2:$G$99,"Done") | D7: =COUNTIFS(Steps!$B$2:$B$99,$A7,Steps!$G$2:$G$99,"Delivered") | E7: =COUNTIFS(Steps!$B$2:$B$99,$A7,Steps!$G$2:$G$99,"In progress") | F7: =COUNTIFS(Steps!$B$2:$B$99,$A7,Steps!$G$2:$G$99,"Blocked") | G7: =COUNTIFS(Steps!$B$2:$B$99,$A7,Steps!$G$2:$G$99,"Parked") | H7: =COUNTIFS(Steps!$B$2:$B$99,$A7,Steps!$G$2:$G$99,"Not started") | I7: =COUNTIFS(Steps!$B$2:$B$99,$A7,Steps!$G$2:$G$99,"Out of scope") | J7: Phases 1-5 and 9-13 done. THE POC IS COMPLETE: 199+ tests green and the demo script runs 27/27 against a live service. docs/POC-ASSESSMENT.md carries the five answers and the verdict (GO, with two conditions). Remaining Build steps: the reconciliation job (61) and reading demo numbers (81). Phase 6/7 Transport and Phase 8 Violations are PARKED — see the Parked tab.
A8: LLM track | B8: =COUNTIF(Steps!$B$2:$B$99,$A8) | C8: =COUNTIFS(Steps!$B$2:$B$99,$A8,Steps!$G$2:$G$99,"Done") | D8: =COUNTIFS(Steps!$B$2:$B$99,$A8,Steps!$G$2:$G$99,"Delivered") | E8: =COUNTIFS(Steps!$B$2:$B$99,$A8,Steps!$G$2:$G$99,"In progress") | F8: =COUNTIFS(Steps!$B$2:$B$99,$A8,Steps!$G$2:$G$99,"Blocked") | G8: =COUNTIFS(Steps!$B$2:$B$99,$A8,Steps!$G$2:$G$99,"Parked") | H8: =COUNTIFS(Steps!$B$2:$B$99,$A8,Steps!$G$2:$G$99,"Not started") | I8: =COUNTIFS(Steps!$B$2:$B$99,$A8,Steps!$G$2:$G$99,"Out of scope") | J8: Blocked on procurement and real ticket text. Steps 7-9 need nobody and can start any time.
A9: TOTAL | B9: =SUM(B6:B8) | C9: =SUM(C6:C8) | D9: =SUM(D6:D8) | E9: =SUM(E6:E8) | F9: =SUM(F6:F8) | G9: =SUM(G6:G8) | H9: =SUM(H6:H8) | I9: =SUM(I6:I8)
A11: Complete | B11: =IFERROR(C9/B9,0) | C11: Done + Delivered | D11: =IFERROR((C9+D9)/B9,0)
A12: Complete (in scope) | B12: =IFERROR(C9/(B9-I9),0) | C12: Out-of-scope steps excluded from the denominator

Sheet Next up
A1: Step | B1: What | C1: Who | D1: Note
A2: — | B2: RUN tools/uat-probe-2.sql and uat-probe-3.sql | C2: You | D2: Closes four open items in one pass: the two wrong column names, paise-vs-rupees on transport_charges, N3 (the PayU link) and N2 (the order_status_code values). Command is in docs/WALKTHROUGH-NOTES.md §8.
A3: — | B3: FIX the two wrong column names once probe 2 lands | C3: Me | D3: arrived_at300_m and order_type do not exist. MySQL 1054 kills the WHOLE Transport SELECT, so on real data Transport does not degrade - it stops. Flip both requiredColumns markers from inferred to confirmed in the same edit.
A4: 55 | B4: BUILD the transport credit service | C4: Me | D4: ActionRegistry holds only AUTO_CREDIT_WALLET, so every transport T2 decides correctly then escalates. This is the difference between a demo where the bot explains what it would do and one where it moves money.
A5: — | B5: WIRE the job lat/long behind cs_address (Q6) | C5: Me | D5: Path 3 distance is null, so transport rules 8 and 9 are dead.
A6: — | B6: N4 — the SELECT-only GRANT on all three catalogs | C6: You | D6: IN PROGRESS, creds requested 15 Sept. 15 of 26 rules cannot read their facts without it. Confirm all three catalogs are on ONE MySQL host.
A7: — | B7: N2 — which unassign_status_code value is NR, and which is CR | C7: You | D7: BLOCKS transport rules 5a/5b, 6, 7. NR auto-credits and CR denies, so a wrong mapping pays the wrong partners.
A8: — | B8: N3 — which column links a wallet credit to a PayU transaction | C8: You | D8: BLOCKS alreadyCredited on Recharge. A wrong "not yet credited" pays twice.
A9: — | B9: DECISION: UPHOLD in the demo, or ship 4 of 5 outcome types? | C9: You | D9: Violations are out of scope, and UPHOLD went with them. VIOL_T1_SAMEDAY_LEAVE (SP_102, exists, needs no blocked answer) restores it for one concern. See docs/SCOPE-VIOLATIONS-OUT.md.
A10: — | B10: Partial-kilometre rounding — prorate, round up, or round down? | C10: You | D10: The Decision Matrix marks it OPEN. The code prorates, because that is the only one of the three that invents nothing.
A11: — | B11: D-1 — hosting | C11: You | D11: The Decision Brief lists it open; the Engineering Design states it settled. They disagree.
A12: — | B12: Job lat/long behind cs_address (Q6) — wire it | C12: Me | D12: Answered by the Decision Matrix: the job location is the CUSTOMER address, not tbl_order. Needed for Transport Path 3.
... A14: 10-11, 15-22 | B14: LLM measurement track | C14: Procurement | D14: Needs an API key and 150-200 labelled real Hinglish messages. Steps 7-9 and 12-14 are done and need nobody.

Sheet Parked
A1: What | B1: Steps | C1: Why it is parked | D1: What unparks it | E1: Who | F1: What the POC loses meanwhile
A2: Violations — OUT OF POC SCOPE (not parked) | B2: 62-67 | C2: Removed from the POC on 15 Sept. R1-R13 are sub-reasons under SP_103, but which column holds the sub-reason could not be established, and a query for a column that does not exist returns zero rows - which matched the REMOVE row and would have auto-removed violations never checked. V4 already had both concerns inactive, so nothing in the running service changes. | D2: Nothing. This is not waiting on anybody. A later violations phase would start from the reasoning in docs/DEFERRED.md D-A. | E2: — | F2: No volume: violations carry no June figure, so 9,542 and 7.7% are unchanged. What is lost is outcome-type coverage - UPHOLD, state-change-without-money and the concern-level durable counter, 3 of the 20 coverage-matrix rows. VIOL_T1_SAMEDAY_LEAVE (SP_102, exists, needs no blocked answer) would restore all three.
A3: Phase 6 — Transport end to end | B3: 53-57 | C3: To be done last, by agreement. The rate and the path selector are SETTLED - the Decision Matrix closed D-B and D-C. What is left is N2, the job lat/long behind cs_address, and a mock credit service. | D3: Answer N2 (which unassign_status_code is NR, which is CR). Then: cs_address wiring and the mock TransportCreditService at step 55. | E3: Project owner (D-B, D-C), then me | F3: The highest-volume concern in the build (5,615/month) decides correctly but cannot pay. In the demo it reaches a person instead — which is the true state, not a bug. Cap escalation IS demonstrable, because it produces a ticket rather than a payment.
A4: Phase 7 — the reconciliation job | B4: 61 | C4: BUILT 14 Sept. ReconciliationService reads both directions and corrects nothing; 5 tests green. Row kept for history. | D4: Done - nothing outstanding. | E4: Me | F4: The one check that would catch a payment the system believes it made and did not.
A5: The LLM track | B5: 10-11, 15-22 | C5: No API key and no model decision, so nothing can be measured. Blocked on procurement, not on design. | D5: A key and a budget owner. Steps 7-9 (task spec, NFRs, PII position) need nobody and can be written at any time. | E5: Procurement / project owner | F5: U-2, classifier accuracy, must be reported as NOT ASSESSED and never as passed. Fixtures written by the person building the classifier will always classify well; that is not evidence. The stub is a real bean, so routing, the confidence floor, the clarification loop and the degradation path are all built and demonstrable now.
A6: Agent-connect triggers B, D, E | B6: — | C6: Out of POC scope by the plan. Trigger A, the bounding rule and C's confidence threshold are in scope and built. | D6: Production work. Trigger D in particular needs the shared trigger table from the Engineering Design — it cannot be a column bolted onto each concern's own table without leaving silent holes in the ones that get missed. | E6: Production phase | F6: Nothing the POC was meant to answer. Stated here because it is easy to assume present.

Sheet Steps
A1: Step | B1: Track | C1: Phase | D1: Task | E1: Detail | F1: Type | G1: Status | H1: Note / blocked by | I1: Owner | J1: My notes
A2: 1 | B2: R&D ladder | C2: Component R&D ladder | D2: Run the Flowable process-engine spike | E2: Start here — it is the single dependency that could invalidate the architecture, and the one with the steepest learning curve. | F2: Task | G2: Done
A3: 2 | B3: R&D ladder | C3: Component R&D ladder | D3: Run the DMN spike, including the deliberately-wrong row order | F3: Task | G3: Done
A4: 3 | B4: R&D ladder | C4: Component R&D ladder | D4: Run the REQUIRES_NEW spike, both with and without the annotation | E4: The negative case matters more than the positive one — it proves the test would catch a regression. | F4: Task | G4: Done
A5: 4 | B5: R&D ladder | C5: Component R&D ladder | D5: Run the Togglz, Resilience4j and Flyway spikes | F5: Task | G5: Done
A6: 5 | B6: R&D ladder | C6: Component R&D ladder | D6: Run the FastAPI + Pydantic spike against a stubbed model response | F6: Task | G6: Done
A7: 6 | B7: R&D ladder | C7: Component R&D ladder | D7: GateWrite one page per component: what it does, how it is wired, and what surprised you | E7: If a component cannot be explained in a page, it is not understood well enough to build on. This page is also the seed of the production runbook. | F7: Gate | G7: Done
A8: 7 | B8: LLM track | C8: 3a — Define what the model has to do | D8: Write the task spec: closed-set classification of short Hinglish text, two variants — one concern's reason list, and the full L1/L2 taxonomy | E8: This is a narrow, cheap task. Naming it precisely stops the conversation drifting toward general-purpose assistants, which is a different and far more expensive purchase. | F8: Task | G8: Done | H8: Done — docs/LLM-TASK-SPEC.md §1. Closed-set classification into a taxonomy the service already owns. States what it is NOT, because each has been mistaken for it: not open-ended understanding, not a decision, not a threshold (the floor lives in the tables so a business owner can tune it), not a conversation. Every sentence a partner reads comes from a template — that is why a wrong classification costs a reroute, not a wrong promise about money.
A9: 8 | B9: LLM track | C9: 3a — Define what the model has to do | D9: Write the non-functional requirements | E9: Structured output support · p95 latency inside the 3s timeout with headroom · cost per thousand classifications at projected volume · rate limits and burst behaviour · data residency · retention and whether a zero-retention mode exists · availability commitment · how hard it is to swap out later. | F9: Task | G9: Done | H9: Done — §2. p95 under 3s because the client already enforces that timeout; a slower model degrades to a human, so you pay for capability you do not use. Cost stated per 1,000 CALLS, not per token: tokenisers differ and Hinglish tokenises worse than English. Degradation must stay indistinguishable from a no-match — already built.
A10: 9 | B10: LLM track | C10: 3a — Define what the model has to do | D10: Decide the PII position before talking to any vendor | E10: Partner free text can contain names, phone numbers and addresses. Decide whether text is redacted before it leaves the network, and whether that is a hard requirement or a preference — it eliminates some options outright. | F10: Task | G10: Done | H10: Done — §3. Recommended position: zero retention, no training on our data, processing region in the contract. SEQUENCE MATTERS: run the compliance filter BEFORE measuring accuracy, or the best-scoring candidate becomes the one everybody argues to accept. The Python service already enforces the boundary structurally — no DB credentials, no identifier field in the schema.
A11: 10 | B11: LLM track | C11: 3b — Build the harness | D11: Extract real free-text from historical tickets — unavailable; write Hinglish fixtures instead | E11: 20–30 strings, phrasing taken from the concern names themselves. Enough to exercise routing, the threshold, the clarification loop and degradation. Not enough to claim accuracy: fixtures written by the builder always classify well. Keep the real extract as a follow-up — the harness is built to accept it unchanged. | F11: Task | G11: Blocked | H11: No historical text — Hinglish fixtures instead
A12: 11 | B12: LLM track | C12: 3b — Build the harness | D12: Label the fixtures into the mapping's own categories anyway | E12: Categories come from the concern mapping, never invented. Labelling fixtures is still worth doing — it forces the category list to be exercised and surfaces overlaps between categories before a real test set exists. | F12: Task | G12: Blocked | H12: Depends on fixtures
A13: 12 | B13: LLM track | C13: 3b — Build the harness | D13: Write the scorer: accuracy, per-class confusion matrix, p95 latency, cost per call | E13: The confusion matrix matters more than the headline number — two categories bleeding into each other is fixable by merging them; uniform error is not. | F13: Task | G13: Done | H13: Done — classifier-service/harness/score.py. Reports accuracy, per-class confusion, false-match vs missed-match SEPARATELY (a false match sends the partner confidently into the wrong flow; a missed match hands them to a person, which is the design working), risk recall never averaged into accuracy, p95 against the 3s budget, and cost per 1,000 calls. A call failure scores as a no-match because that is what the service does with one.
A14: 13 | B14: LLM track | C14: 3b — Build the harness | D14: Define one prompt, versioned as a file, used identically across every candidate | E14: Tuning the prompt per vendor makes the comparison meaningless. | F14: Task | G14: Done | H14: Done — classifier-service/prompts/classify-v1.txt. Versioned so every candidate is measured on an IDENTICAL prompt: tuned per vendor, a model comparison becomes a prompt-engineering comparison and the winner is whoever was tuned last. {CATEGORIES} is substituted at call time from the ACTIVE catalogue, so a model can never name a concern nobody built.
A15: 14 | B15: LLM track | C15: 3c — Shortlist and decide | D15: Shortlist across three categories, not three brands | E15: Hosted frontier APIs — best accuracy, highest per-call cost, data leaves the network. Hosted small/cheap tiers — most vendors offer a smaller model that is usually sufficient for closed-set classification. Open-weight self-hosted — no per-call cost, no data egress, but infrastructure and ops become yours. Pricing and model lineups change constantly; pull current figures at decision time rather than trusting any written comparison. | F15: Task | G15: Done | H15: Done — §4. Three CATEGORIES, not three brands: hosted frontier, hosted cheap, self-hosted open. Evaluate the cheap tier FIRST — this is closed-set classification into under forty categories, not open-ended reasoning, and a frontier model would be paying for unused capability on every call forever. Exit criteria agreed before the numbers exist: >=90% holds, 75-90% raises the floor, <75% makes free text a fallback.
A16: 15 | B16: LLM track | C16: 3c — Shortlist and decide | D16: Run every candidate through the harness on the same test set and the same prompt | F16: Task | G16: Blocked | H16: Needs harness + a vendor
A17: 16 | B17: LLM track | C17: 3c — Shortlist and decide | D17: Check the cheap tier first | E17: This task is short-text classification into a fixed list. If a small model reaches the threshold, the frontier model's advantage is worth nothing here and costs several times more per call at 50,000 sessions a month. | F17: Task | G17: Blocked | H17: Needs step 15
A18: 17 | B18: LLM track | C18: 3c — Shortlist and decide | D18: DecisionRecord the choice with its numbers, and the runner-up with its numbers | E18: The runner-up matters: it is the fallback if the first choice fails a security review, changes pricing, or degrades. | F18: Decision | G18: Blocked | H18: Needs step 15
A19: 18 | B19: LLM track | C19: 3d — Procure and secure the key | D19: Identify the budget owner and get a spend ceiling approved against the measured cost-per-call | E19: Bring a number from step 15, not an estimate. | F19: Task | G19: Blocked | H19: Needs measured cost from step 15
A20: 19 | B20: LLM track | C20: 3d — Procure and secure the key | D20: Security review and data-processing agreement | E20: Usually the longest single item. Start it the moment the shortlist exists — it can run against two candidates in parallel. | F20: Task | G20: Blocked | H20: Needs shortlist
A21: 20 | B21: LLM track | C21: 3d — Procure and secure the key | D21: Billing account, then separate keys per environment | F21: Task | G21: Blocked | H21: Needs step 19
A22: 21 | B22: LLM track | C22: 3d — Procure and secure the key | D22: Keys into a secret manager with a rotation policy — never in the repo, never in a plain environment file | E22: Decide rotation cadence and who holds the break-glass copy at the same time, not later. | F22: Task | G22: Blocked | H22: Needs step 20
A23: 22 | B23: LLM track | C23: 3d — Procure and secure the key | D23: Spend alerting on the billing account | E23: A retry loop against a paid API is a financial incident, not just a bug. | F23: Task | G23: Blocked | H23: Needs step 20
A24: 23 | B24: Build | C24: Phase 1 — Skeleton and data model | D24: Spring Boot service, standalone, structured as the production package layout | E24: Split by layer from day one: api, session, catalogue, process, decision, facts, action, safety, agent. Renaming packages later is cheap; discovering the boundaries later is not. | F24: Task | G24: Done | H24: Done — verified by mvn test on 14 Sep, 6/6 green
A25: 24 | B25: Build | C25: Phase 1 — Skeleton and data model | D25: Dependencies: web, data-jpa, flyway, flowable-spring-boot-starter, togglz, resilience4j, driver, test containers | F25: Task | G25: Done | H25: Done — all versions resolve; Flyway module corrected to Boot 3.2 line
A26: 25 | B26: Build | C26: Phase 1 — Skeleton and data model | D26: Two datasources: the service's own schema, and a second, read-only one | E26: Points at a seeded local database for now, at the replica later — the code does not know the difference. Keep it read-only at the connection level from day one, so the substitution never quietly becomes a write path. | F26: Task | G26: Done | H26: Done — UAT is the SECOND datasource, read-only, no JPA/Flyway/Flowable on it
A27: 26 | B27: Build | C27: Phase 1 — Skeleton and data model | D27: Flyway migrations for six tables: concern_catalogue, help_session, ticket, ticket_action, conversation_message, escalation_context | F27: Task | G27: Done | H27: Done — V1__core_schema.sql applies cleanly
A28: 27 | B28: Build | C28: Phase 1 — Skeleton and data model | D28: Plus one the mapping forces: sp_counter — durable per-SP tallies with a reset boundary | E28: The pooled emergency count, the monthly period-leave count and the 25-job cycle allowances are state this engine owns, not facts it reads. Nothing in the earlier design held them. | F28: Task | G28: Done | H28: Done — sp_counter included
A29: 28 | B29: Build | C29: Phase 1 — Skeleton and data model | D29: Unique constraint on ticket_action.idempotency_key; index ticket(sp_id, l2_concern, created_at) | F29: Task | G29: Done | H29: Done — asserted by SchemaAndCatalogueTest
A30: 29 | B30: Build | C30: Phase 1 — Skeleton and data model | D30: Entities, repositories, and HelpSessionService / TicketService / TicketActionRecorder | F30: Task | G30: Done | H30: Done — entities + repositories + recorder
A31: 30 | B31: Build | C31: Phase 1 — Skeleton and data model | D31: CriticalrecordAttempt() annotated @Transactional(propagation = REQUIRES_NEW), with the paired test from spike 3 promoted into the real test suite | F31: Critical | G31: Done | H31: Done — rollback test green in the real suite
A32: 31 | B32: Build | C32: Phase 1 — Skeleton and data model | D32: CheckpointApp boots on an empty database; our seven tables and ~25 ACT_* tables all appear | F32: Checkpoint | G32: Done | H32: Done — 6/6 tests pass; 7 tables + ACT_* confirmed on H2. Postgres boot still to run.
A33: 32 | B33: Build | C33: Phase 2 — Catalogue and L1 → L2 routing | D33: Seed concern_catalogue from the generated CSV — all 38 rows, 30 of them inactive | E33: Seed the full taxonomy even though only 8 are built. It makes the L1 menu real, and an SP selecting an unbuilt concern must degrade gracefully rather than 500. | F33: Task | G33: Done | H33: Done — all 38 seeded, 8 active (V2)
A34: 33 | B34: Build | C34: Phase 2 — Catalogue and L1 → L2 routing | D34: Add the columns this mapping needs beyond the original design: mandatory_human, outcome_types, active | F34: Task | G34: Done | H34: Done — V3 adds outcome_types, backfilled for all 38; mandatory_human + active already in V1
A35: 34 | B35: Build | C35: Phase 2 — Catalogue and L1 → L2 routing | D35: GET /help/concerns returns L1 paths; GET /help/concerns/{l1} returns active L2s | E35: Driven entirely from the catalogue. No hard-coded list anywhere. | F35: Task | G35: Done | H35: Done — GET /help/concerns and /help/concerns/{l1}, derived from the table, no hard-coded list
A36: 35 | B36: Build | C36: Phase 2 — Catalogue and L1 → L2 routing | D36: POST /help/sessions and POST /help/sessions/{id}/input with a nextStep descriptor | E36: Types: menu, dropdown, text, message, deeplink, closed. The backend owns all flow logic; the client is a renderer. | F36: Task | G36: Done | H36: Done — POST /help/sessions + /input, nextStep descriptor persisted as JSON on help_session
A37: 36 | B37: Build | C37: Phase 2 — Catalogue and L1 → L2 routing | D37: GET /help/sessions/{id} for reconnect | E37: Reads nextStep from the session row, never from process variables — those are deleted when an instance completes. | F37: Task | G37: Done | H37: Done — GET /help/sessions/{id}; reconnect payload asserted identical to the response payload
A38: 37 | B38: Build | C38: Phase 2 — Catalogue and L1 → L2 routing | D38: Selecting an inactive concern returns a defined "not available" step | E38: 30 of 38 rows are inactive. This path will be hit constantly. | F38: Task | G38: Done | H38: Done — CONCERN_NOT_AVAILABLE for inactive, unknown, and wrong-path codes; status CLOSED_NOT_AVAILABLE
A39: 38 | B39: Build | C39: Phase 3 — First concern end to end — T0 | D39: FORGET_MPIN: BPMN with a start event, one Service Task, one end event | F39: Task | G39: Done | H39: Done — forget-mpin.bpmn20.xml: start, one Service Task, end
A40: 39 | B40: Build | C40: Phase 3 — First concern end to end — T0 | D40: Returns a deeplink step and closes the session | F40: Task | G40: Done | H40: Done — deeplink step (configurable), session closes CLOSED_DEFLECTED
...

Sheet Evidence
A1: Spike | B1: What was tested | C1: Result | D1: What it settled
A2: 1 | B2: Flowable pause / JVM death / resume | C2: PASSED | D2: ADR-001 holds — the reason for embedding an engine at all
A3: 2 | B3: DMN hit policy and row order | C3: PASSED | D3: Row order IS logic. A table with no catch-all returns null — 13 of 38 concerns are written that way
A4: 3 | B4: REQUIRES_NEW through a rollback | C4: PASSED | D4: ADR-005 holds. Negative test passed too, so the test has teeth
A5: 4 | B5: Togglz runtime flip | C5: PASSED | D5: Kill switch works with no restart
A6: 4 | B6: Togglz misspelt flag name | C6: PASSED — A HOLE | D6: Unknown flag reads as "off" SILENTLY. Startup validation is now mandatory — FeatureNameValidator exists because of this
A7: 4 | B7: Resilience4j circuit breaker | C7: PASSED | D7: Once OPEN the body stops executing, so a dead dependency stops costing a timeout per request
A8: 4 | B8: Flyway + Flowable, one database | C8: PASSED | D8: They coexist
A9: 5 | B9: Classifier rejects bad model output | C9: PASSED | D9: Hallucinated category, confidence 1.7, prose, missing field — all stopped at the boundary
A10: — | B10: U-2 classifier accuracy | C10: NOT ASSESSED | D10: No key, no real ticket text. Must never be reported as passed
A11: build | B11: DMN modeller re-save (DMN 1.5 namespace) | C11: FOUND IN THE BUILD — A HOLE | D11: Flowable 7.0.1 parses ONLY DMN 1.3 (20191111). One re-saved file stopped dmnEngineConfiguration, killed the Spring context and failed every @SpringBootTest — 80 errors. DmnNamespaceTest guards it now
A12: build | B12: Fact name spelled differently on the two sides | C12: FOUND IN THE BUILD — A HOLE | D12: arrivedAt300m vs arrivedAt300metre. No error anywhere: the table reads null, never matches, every claim reaches an agent. ProviderContractTest guards it now
... A15: build | B15: An ACTIVE concern pointing at a BPMN file that was never written | C15: FOUND IN THE BUILD — A HOLE | D15: Non-null pointer, no artifact. Nothing failed; the partner met CONCERN_NOT_AVAILABLE and nothing reported it. SchemaAndCatalogueTest now asks both engines whether every process_key and dmn_key resolves
